2021/01/13 09:11:03 : customers_errors 1: Traceback (most recent call last):
  File "/home/hoang/Desktop/v32/cartmigration/controllers/migration.py", line 1036, in migration
    convert = fn_convert_export(main, ext)
  File "/home/hoang/Desktop/v32/cartmigration/models/cart/custom.py", line 944, in convert_customer_export
    customer_data['username'] = customer['customers_firstname'] + customer['last_name']
KeyError: 'last_name'

2021/01/13 09:11:03 : customers_errors 3: Traceback (most recent call last):
  File "/home/hoang/Desktop/v32/cartmigration/controllers/migration.py", line 1036, in migration
    convert = fn_convert_export(main, ext)
  File "/home/hoang/Desktop/v32/cartmigration/models/cart/custom.py", line 944, in convert_customer_export
    customer_data['username'] = customer['customers_firstname'] + customer['last_name']
KeyError: 'last_name'

